Workbook

Sheet 🏠 Dashboard
B2: 💼 FREELANCE BUSINESS MANAGER 2026
B3: Your Complete Business Command Center
B5: 💰 MONTHLY REVENUE | D5: 📋 ACTIVE PROJECTS | F5: 🧾 UNPAID INVOICES
B6: ='💰 Income & Expenses'!C52 | D6: =COUNTIF('📋 Projects'!C4:C53,"Active") | F6: =COUNTIF('🧾 Invoices'!G4:G53,"Unpaid")
B9: 📊 MONTHLY PERFORMANCE OVERVIEW
B10: Month | C10: Revenue | D10: Expenses | E10: Profit | F10: Projects | G10: Invoiced
B11: Jan | C11: 0 | D11: 0 | E11: =C11-D11 | F11: 0 | G11: 0
B12: Feb | C12: 0 | D12: 0 | E12: =C12-D12 | F12: 0 | G12: 0
B13: Mar | C13: 0 | D13: 0 | E13: =C13-D13 | F13: 0 | G13: 0
B14: Apr | C14: 0 | D14: 0 | E14: =C14-D14 | F14: 0 | G14: 0
B15: May | C15: 0 | D15: 0 | E15: =C15-D15 | F15: 0 | G15: 0
B16: Jun | C16: 0 | D16: 0 | E16: =C16-D16 | F16: 0 | G16: 0
B17: Jul | C17: 0 | D17: 0 | E17: =C17-D17 | F17: 0 | G17: 0
B18: Aug | C18: 0 | D18: 0 | E18: =C18-D18 | F18: 0 | G18: 0
B19: Sep | C19: 0 | D19: 0 | E19: =C19-D19 | F19: 0 | G19: 0
B20: Oct | C20: 0 | D20: 0 | E20: =C20-D20 | F20: 0 | G20: 0
B21: Nov | C21: 0 | D21: 0 | E21: =C21-D21 | F21: 0 | G21: 0
B22: Dec | C22: 0 | D22: 0 | E22: =C22-D22 | F22: 0 | G22: 0
B23: TOTAL | C23: =SUM(C11:C22) | D23: =SUM(D11:D22) | E23: =SUM(E11:E22) | F23: =SUM(F11:F22) | G23: =SUM(G11:G22)
B25: ⭐ TOP CLIENTS THIS MONTH
B26: Client Name | C26: Projects | D26: Revenue | E26: Status | F26: Last Contact
B34: 💡 Yellow cells = Enter your data | Green cells = Auto-calculated | Update monthly for accurate reports

Sheet 👥 Clients
B1: 👥 CLIENT DATABASE
B3: Client Name | C3: Company | D3: Email | E3: Phone | F3: Country | G3: Status | H3: Total Projects | I3: Total Revenue | J3: Last Contact
B4: TechStart Inc | C4: David Miller | D4: david@techstart.com | E4: +1-555-0101 | F4: USA | G4: VIP | H4: =COUNTIF('📋 Projects'!D4:D53,B4) | I4: =SUMIF('📋 Projects'!D4:D53,B4,'📋 Projects'!H4:H53)
B5: Creative Agency | C5: Sarah Johnson | D5: sarah@creative.co | E5: +44-20-1234 | F5: UK | G5: Active | H5: =COUNTIF('📋 Projects'!D4:D53,B5) | I5: =SUMIF('📋 Projects'!D4:D53,B5,'📋 Projects'!H4:H53)
B6: EcomStore | C6: Carlos Rivera | D6: carlos@ecom.es | E6: +34-91-1234 | F6: Spain | G6: Active | H6: =COUNTIF('📋 Projects'!D4:D53,B6) | I6: =SUMIF('📋 Projects'!D4:D53,B6,'📋 Projects'!H4:H53)
B7: FoodBrand | C7: Amira Hassan | D7: amira@food.ae | E7: +971-55-1234 | F7: UAE | G7: Lead | H7: =COUNTIF('📋 Projects'!D4:D53,B7) | I7: =SUMIF('📋 Projects'!D4:D53,B7,'📋 Projects'!H4:H53)
B8: Startup Hub | C8: Liu Wei | D8: liu@startup.cn | E8: +86-10-1234 | F8: China | G8: Active | H8: =COUNTIF('📋 Projects'!D4:D53,B8) | I8: =SUMIF('📋 Projects'!D4:D53,B8,'📋 Projects'!H4:H53)
H9: =IF(B9="","",COUNTIF('📋 Projects'!D4:D53,B9)) | I9: =IF(B9="","",SUMIF('📋 Projects'!D4:D53,B9,'📋 Projects'!H4:H53))
H10: =IF(B10="","",COUNTIF('📋 Projects'!D4:D53,B10)) | I10: =IF(B10="","",SUMIF('📋 Projects'!D4:D53,B10,'📋 Projects'!H4:H53))
H11: =IF(B11="","",COUNTIF('📋 Projects'!D4:D53,B11)) | I11: =IF(B11="","",SUMIF('📋 Projects'!D4:D53,B11,'📋 Projects'!H4:H53))
H12: =IF(B12="","",COUNTIF('📋 Projects'!D4:D53,B12)) | I12: =IF(B12="","",SUMIF('📋 Projects'!D4:D53,B12,'📋 Projects'!H4:H53))
H13: =IF(B13="","",COUNTIF('📋 Projects'!D4:D53,B13)) | I13: =IF(B13="","",SUMIF('📋 Projects'!D4:D53,B13,'📋 Projects'!H4:H53))
H14: =IF(B14="","",COUNTIF('📋 Projects'!D4:D53,B14)) | I14: =IF(B14="","",SUMIF('📋 Projects'!D4:D53,B14,'📋 Projects'!H4:H53))
H15: =IF(B15="","",COUNTIF('📋 Projects'!D4:D53,B15)) | I15: =IF(B15="","",SUMIF('📋 Projects'!D4:D53,B15,'📋 Projects'!H4:H53))
H16: =IF(B16="","",COUNTIF('📋 Projects'!D4:D53,B16)) | I16: =IF(B16="","",SUMIF('📋 Projects'!D4:D53,B16,'📋 Projects'!H4:H53))
H17: =IF(B17="","",COUNTIF('📋 Projects'!D4:D53,B17)) | I17: =IF(B17="","",SUMIF('📋 Projects'!D4:D53,B17,'📋 Projects'!H4:H53))
H18: =IF(B18="","",COUNTIF('📋 Projects'!D4:D53,B18)) | I18: =IF(B18="","",SUMIF('📋 Projects'!D4:D53,B18,'📋 Projects'!H4:H53))
H19: =IF(B19="","",COUNTIF('📋 Projects'!D4:D53,B19)) | I19: =IF(B19="","",SUMIF('📋 Projects'!D4:D53,B19,'📋 Projects'!H4:H53))
H20: =IF(B20="","",COUNTIF('📋 Projects'!D4:D53,B20)) | I20: =IF(B20="","",SUMIF('📋 Projects'!D4:D53,B20,'📋 Projects'!H4:H53))
H21: =IF(B21="","",COUNTIF('📋 Projects'!D4:D53,B21)) | I21: =IF(B21="","",SUMIF('📋 Projects'!D4:D53,B21,'📋 Projects'!H4:H53))
H22: =IF(B22="","",COUNTIF('📋 Projects'!D4:D53,B22)) | I22: =IF(B22="","",SUMIF('📋 Projects'!D4:D53,B22,'📋 Projects'!H4:H53))
H23: =IF(B23="","",COUNTIF('📋 Projects'!D4:D53,B23)) | I23: =IF(B23="","",SUMIF('📋 Projects'!D4:D53,B23,'📋 Projects'!H4:H53))
H24: =IF(B24="","",COUNTIF('📋 Projects'!D4:D53,B24)) | I24: =IF(B24="","",SUMIF('📋 Projects'!D4:D53,B24,'📋 Projects'!H4:H53))
H25: =IF(B25="","",COUNTIF('📋 Projects'!D4:D53,B25)) | I25: =IF(B25="","",SUMIF('📋 Projects'!D4:D53,B25,'📋 Projects'!H4:H53))
H26: =IF(B26="","",COUNTIF('📋 Projects'!D4:D53,B26)) | I26: =IF(B26="","",SUMIF('📋 Projects'!D4:D53,B26,'📋 Projects'!H4:H53))
H27: =IF(B27="","",COUNTIF('📋 Projects'!D4:D53,B27)) | I27: =IF(B27="","",SUMIF('📋 Projects'!D4:D53,B27,'📋 Projects'!H4:H53))
H28: =IF(B28="","",COUNTIF('📋 Projects'!D4:D53,B28)) | I28: =IF(B28="","",SUMIF('📋 Projects'!D4:D53,B28,'📋 Projects'!H4:H53))
H29: =IF(B29="","",COUNTIF('📋 Projects'!D4:D53,B29)) | I29: =IF(B29="","",SUMIF('📋 Projects'!D4:D53,B29,'📋 Projects'!H4:H53))
H30: =IF(B30="","",COUNTIF('📋 Projects'!D4:D53,B30)) | I30: =IF(B30="","",SUMIF('📋 Projects'!D4:D53,B30,'📋 Projects'!H4:H53))
H31: =IF(B31="","",COUNTIF('📋 Projects'!D4:D53,B31)) | I31: =IF(B31="","",SUMIF('📋 Projects'!D4:D53,B31,'📋 Projects'!H4:H53))
H32: =IF(B32="","",COUNTIF('📋 Projects'!D4:D53,B32)) | I32: =IF(B32="","",SUMIF('📋 Projects'!D4:D53,B32,'📋 Projects'!H4:H53))
H33: =IF(B33="","",COUNTIF('📋 Projects'!D4:D53,B33)) | I33: =IF(B33="","",SUMIF('📋 Projects'!D4:D53,B33,'📋 Projects'!H4:H53))
H34: =IF(B34="","",COUNTIF('📋 Projects'!D4:D53,B34)) | I34: =IF(B34="","",SUMIF('📋 Projects'!D4:D53,B34,'📋 Projects'!H4:H53))
H35: =IF(B35="","",COUNTIF('📋 Projects'!D4:D53,B35)) | I35: =IF(B35="","",SUMIF('📋 Projects'!D4:D53,B35,'📋 Projects'!H4:H53))
H36: =IF(B36="","",COUNTIF('📋 Projects'!D4:D53,B36)) | I36: =IF(B36="","",SUMIF('📋 Projects'!D4:D53,B36,'📋 Projects'!H4:H53))
H37: =IF(B37="","",COUNTIF('📋 Projects'!D4:D53,B37)) | I37: =IF(B37="","",SUMIF('📋 Projects'!D4:D53,B37,'📋 Projects'!H4:H53))
H38: =IF(B38="","",COUNTIF('📋 Projects'!D4:D53,B38)) | I38: =IF(B38="","",SUMIF('📋 Projects'!D4:D53,B38,'📋 Projects'!H4:H53))
H39: =IF(B39="","",COUNTIF('📋 Projects'!D4:D53,B39)) | I39: =IF(B39="","",SUMIF('📋 Projects'!D4:D53,B39,'📋 Projects'!H4:H53))
H40: =IF(B40="","",COUNTIF('📋 Projects'!D4:D53,B40)) | I40: =IF(B40="","",SUMIF('📋 Projects'!D4:D53,B40,'📋 Projects'!H4:H53))
H41: =IF(B41="","",COUNTIF('📋 Projects'!D4:D53,B41)) | I41: =IF(B41="","",SUMIF('📋 Projects'!D4:D53,B41,'📋 Projects'!H4:H53))
...

Sheet 📋 Projects
B1: 📋 PROJECT TRACKER
B3: # | C3: Project Name | D3: Client | E3: Category | F3: Status | G3: Start Date | H3: Deadline | I3: Value ($) | J3: % Done | K3: Notes
B4: 1 | C4: Website Redesign | D4: TechStart Inc | E4: Web Design | F4: Active | G4: 2026-01-15 | H4: 2026-03-01 | I4: 3500 | J4: 0.75
B5: 2 | C5: SEO Campaign | D5: Creative Agency | E5: SEO | F5: Active | G5: 2026-02-01 | H5: 2026-04-30 | I5: 1200 | J5: 0.4
B6: 3 | C6: App Development | D6: EcomStore | E6: Development | F6: Active | G6: 2026-01-20 | H6: 2026-05-15 | I6: 8000 | J6: 0.25
B7: 4 | C7: Content Writing | D7: FoodBrand | E7: Writing | F7: Completed | G7: 2025-12-01 | H7: 2026-01-31 | I7: 600 | J7: 1
B8: 5 | C8: Social Media | D8: Startup Hub | E8: Social Media | F8: Planning | G8: 2026-03-01 | H8: 2026-06-30 | I8: 900 | J8: 0
B9: 6 | I9: 0
B10: 7 | I10: 0
B11: 8 | I11: 0
B12: 9 | I12: 0
B13: 10 | I13: 0
B14: 11 | I14: 0
B15: 12 | I15: 0
B16: 13 | I16: 0
B17: 14 | I17: 0
B18: 15 | I18: 0
B19: 16 | I19: 0
B20: 17 | I20: 0
... B53: 50 | I53: 0
C54: TOTALS | I54: =SUM(I4:I53) | J54: =AVERAGE(J4:J53)

Sheet 🧾 Invoices
B1: 🧾 INVOICE TRACKER
B3: Invoice # | C3: Client | D3: Project | E3: Amount | F3: Date Sent | G3: Due Date | H3: Status | I3: Days Overdue
B4: INV-001 | C4: TechStart Inc | D4: Website Redesign | E4: 1750 | F4: 2026-01-15 | G4: 2026-01-29 | H4: Paid | I4: =IF(H4="Paid","✅",IF(TODAY()>G4,TODAY()-G4,"On time"))
B5: INV-002 | C5: Creative Agency | D5: SEO Campaign | E5: 600 | F5: 2026-02-01 | G5: 2026-02-15 | H5: Unpaid | I5: =IF(H5="Paid","✅",IF(TODAY()>G5,TODAY()-G5,"On time"))
B6: INV-003 | C6: EcomStore | D6: App Development | E6: 2000 | F6: 2026-02-10 | G6: 2026-02-24 | H6: Overdue | I6: =IF(H6="Paid","✅",IF(TODAY()>G6,TODAY()-G6,"On time"))
B7: INV-004 | C7: FoodBrand | D7: Content Writing | E7: 600 | F7: 2026-01-31 | G7: 2026-02-14 | H7: Paid | I7: =IF(H7="Paid","✅",IF(TODAY()>G7,TODAY()-G7,"On time"))
B8: INV-005 | C8: Startup Hub | D8: Social Media | E8: 450 | F8: 2026-03-01 | G8: 2026-03-15 | H8: Unpaid | I8: =IF(H8="Paid","✅",IF(TODAY()>G8,TODAY()-G8,"On time"))
E9: 0 | H9: Unpaid | I9: =IF(E9=0,"",IF(H9="Paid","✅",IF(TODAY()>G9,TODAY()-G9,"On time")))
E10: 0 | H10: Unpaid | I10: =IF(E10=0,"",IF(H10="Paid","✅",IF(TODAY()>G10,TODAY()-G10,"On time")))
E11: 0 | H11: Unpaid | I11: =IF(E11=0,"",IF(H11="Paid","✅",IF(TODAY()>G11,TODAY()-G11,"On time")))
E12: 0 | H12: Unpaid | I12: =IF(E12=0,"",IF(H12="Paid","✅",IF(TODAY()>G12,TODAY()-G12,"On time")))
E13: 0 | H13: Unpaid | I13: =IF(E13=0,"",IF(H13="Paid","✅",IF(TODAY()>G13,TODAY()-G13,"On time")))
E14: 0 | H14: Unpaid | I14: =IF(E14=0,"",IF(H14="Paid","✅",IF(TODAY()>G14,TODAY()-G14,"On time")))
E15: 0 | H15: Unpaid | I15: =IF(E15=0,"",IF(H15="Paid","✅",IF(TODAY()>G15,TODAY()-G15,"On time")))
E16: 0 | H16: Unpaid | I16: =IF(E16=0,"",IF(H16="Paid","✅",IF(TODAY()>G16,TODAY()-G16,"On time")))
E17: 0 | H17: Unpaid | I17: =IF(E17=0,"",IF(H17="Paid","✅",IF(TODAY()>G17,TODAY()-G17,"On time")))
E18: 0 | H18: Unpaid | I18: =IF(E18=0,"",IF(H18="Paid","✅",IF(TODAY()>G18,TODAY()-G18,"On time")))
E19: 0 | H19: Unpaid | I19: =IF(E19=0,"",IF(H19="Paid","✅",IF(TODAY()>G19,TODAY()-G19,"On time")))
E20: 0 | H20: Unpaid | I20: =IF(E20=0,"",IF(H20="Paid","✅",IF(TODAY()>G20,TODAY()-G20,"On time")))
... E53: 0 | H53: Unpaid | I53: =IF(E53=0,"",IF(H53="Paid","✅",IF(TODAY()>G53,TODAY()-G53,"On time")))
B55: SUMMARY | E55: Total Invoiced | F55: Total Paid | G55: Total Unpaid | H55: Total Overdue
E56: =SUM(E4:E53) | F56: =SUMIF(H4:H53,"Paid",E4:E53) | G56: =SUMIF(H4:H53,"Unpaid",E4:E53) | H56: =SUMIF(H4:H53,"Overdue",E4:E53)

Sheet 💰 Income & Expenses
B1: 💰 INCOME & EXPENSE TRACKER
B3: Date | C3: Description | D3: Client/Vendor | E3: Amount | F3: Type | G3: Category
B4: 2026-01-29 | C4: Website Redesign P1 | D4: TechStart Inc | E4: 1750 | F4: Income | G4: Project Payment
B5: 2026-01-31 | C5: Adobe CC | D5: Adobe | E5: 54 | F5: Expense | G5: Software
B6: 2026-02-14 | C6: Content Writing | D6: FoodBrand | E6: 600 | F6: Income | G6: Project Payment
B7: 2026-02-15 | C7: Office Supplies | D7: Amazon | E7: 35 | F7: Expense | G7: Office
B8: 2026-02-20 | C8: SEO Tools | D8: Ahrefs | E8: 99 | F8: Expense | G8: Software
B9: 2026-03-01 | C9: Retainer Fee | D9: Creative Agency | E9: 500 | F9: Income | G9: Retainer
E10: 0 | F10: Income | G10: Project Payment
E11: 0 | F11: Income | G11: Project Payment
E12: 0 | F12: Income | G12: Project Payment
E13: 0 | F13: Income | G13: Project Payment
E14: 0 | F14: Income | G14: Project Payment
E15: 0 | F15: Income | G15: Project Payment
E16: 0 | F16: Income | G16: Project Payment
E17: 0 | F17: Income | G17: Project Payment
E18: 0 | F18: Income | G18: Project Payment
E19: 0 | F19: Income | G19: Project Payment
E20: 0 | F20: Income | G20: Project Payment
E21: 0 | F21: Income | G21: Project Payment
... E51: 0 | F51: Income | G51: Project Payment
C52: =SUMIF(F4:F51,"Income",E4:E51)
B53: TOTALS | D53: Total Income | E53: Total Expenses | F53: Net Profit | G53: Tax Est. (25%)
D54: =SUMIF(F4:F51,"Income",E4:E51) | E54: =SUMIF(F4:F51,"Expense",E4:E51) | F54: =D54-E54 | G54: =SUMIF(F4:F51,"Income",E4:E51)*0.25

Sheet ⏱️ Time Tracker
B1: ⏱️ TIME TRACKER
B3: Date | C3: Task | D3: Client | E3: Start | F3: End | G3: Hours | H3: Rate ($/hr) | I3: Earned
B4: 2026-02-01 | C4: Homepage Design | D4: TechStart Inc | E4: 09:00 | F4: 13:00 | G4: =IF(E4="",0,(TIMEVALUE(F4)-TIMEVALUE(E4))*24) | H4: 85 | I4: =G4*H4
B5: 2026-02-01 | C5: Client Meeting | D5: Creative Agency | E5: 14:00 | F5: 15:00 | G5: =IF(E5="",0,(TIMEVALUE(F5)-TIMEVALUE(E5))*24) | H5: 85 | I5: =G5*H5
B6: 2026-02-02 | C6: SEO Audit | D6: Creative Agency | E6: 09:00 | F6: 12:30 | G6: =IF(E6="",0,(TIMEVALUE(F6)-TIMEVALUE(E6))*24) | H6: 75 | I6: =G6*H6
B7: 2026-02-03 | C7: App Wireframes | D7: EcomStore | E7: 10:00 | F7: 18:00 | G7: =IF(E7="",0,(TIMEVALUE(F7)-TIMEVALUE(E7))*24) | H7: 95 | I7: =G7*H7
B8: 2026-02-04 | C8: Content Writing | D8: FoodBrand | E8: 09:00 | F8: 12:00 | G8: =IF(E8="",0,(TIMEVALUE(F8)-TIMEVALUE(E8))*24) | H8: 65 | I8: =G8*H8
G9: =IF(E9="",0,(TIMEVALUE(F9)-TIMEVALUE(E9))*24) | H9: 0 | I9: =G9*H9
G10: =IF(E10="",0,(TIMEVALUE(F10)-TIMEVALUE(E10))*24) | H10: 0 | I10: =G10*H10
G11: =IF(E11="",0,(TIMEVALUE(F11)-TIMEVALUE(E11))*24) | H11: 0 | I11: =G11*H11
G12: =IF(E12="",0,(TIMEVALUE(F12)-TIMEVALUE(E12))*24) | H12: 0 | I12: =G12*H12
G13: =IF(E13="",0,(TIMEVALUE(F13)-TIMEVALUE(E13))*24) | H13: 0 | I13: =G13*H13
G14: =IF(E14="",0,(TIMEVALUE(F14)-TIMEVALUE(E14))*24) | H14: 0 | I14: =G14*H14
G15: =IF(E15="",0,(TIMEVALUE(F15)-TIMEVALUE(E15))*24) | H15: 0 | I15: =G15*H15
G16: =IF(E16="",0,(TIMEVALUE(F16)-TIMEVALUE(E16))*24) | H16: 0 | I16: =G16*H16
G17: =IF(E17="",0,(TIMEVALUE(F17)-TIMEVALUE(E17))*24) | H17: 0 | I17: =G17*H17
G18: =IF(E18="",0,(TIMEVALUE(F18)-TIMEVALUE(E18))*24) | H18: 0 | I18: =G18*H18
G19: =IF(E19="",0,(TIMEVALUE(F19)-TIMEVALUE(E19))*24) | H19: 0 | I19: =G19*H19
G20: =IF(E20="",0,(TIMEVALUE(F20)-TIMEVALUE(E20))*24) | H20: 0 | I20: =G20*H20
... G51: =IF(E51="",0,(TIMEVALUE(F51)-TIMEVALUE(E51))*24) | H51: 0 | I51: =G51*H51
B53: TOTALS | G53: =SUM(G4:G51) | I53: =SUM(I4:I51)

Sheet 📊 Reports
B1: 📊 AUTO REPORTS
B3: 💰 FINANCIAL SUMMARY
B4: Total Revenue | C4: ='💰 Income & Expenses'!D54
B5: Total Expenses | C5: ='💰 Income & Expenses'!E54
B6: Net Profit | C6: ='💰 Income & Expenses'!F54
B7: Tax Estimate | C7: ='💰 Income & Expenses'!G54
B8: Profit Margin % | C8: =IF(D4=0,0,F4/D4*100)
B9: Monthly Average | C9: =F4/12
B10: Best Month | C10: =MAX('🏠 Dashboard'!C11:C22)
B11: Worst Month | C11: =MIN(IF('🏠 Dashboard'!C11:C22>0,'🏠 Dashboard'!C11:C22))
B13: 📋 PROJECT SUMMARY
B14: Total Projects | C14: =COUNTA('📋 Projects'!C4:C53)
B15: Active Projects | C15: =COUNTIF('📋 Projects'!F4:F53,"Active")
B16: Completed | C16: =COUNTIF('📋 Projects'!F4:F53,"Completed")
B17: Total Project Value | C17: =SUM('📋 Projects'!I4:I53)
B18: Avg Project Value | C18: =IFERROR(D28/D25,0)
B19: Completion Rate % | C19: =IFERROR(D26/D25*100,0)
B21: 🧾 INVOICE SUMMARY
B22: Total Invoiced | C22: =SUM('🧾 Invoices'!E4:E53)
B23: Total Paid | C23: =SUMIF('🧾 Invoices'!H4:H53,"Paid",'🧾 Invoices'!E4:E53)
B24: Unpaid | C24: =SUMIF('🧾 Invoices'!H4:H53,"Unpaid",'🧾 Invoices'!E4:E53)
B25: Overdue | C25: =SUMIF('🧾 Invoices'!H4:H53,"Overdue",'🧾 Invoices'!E4:E53)
B26: Collection Rate % | C26: =IFERROR(D38/D37*100,0)
B28: ⏱️ TIME SUMMARY
B29: Total Hours Tracked | C29: =SUM('⏱️ Time Tracker'!G4:G51)
B30: Total Earned | C30: =SUM('⏱️ Time Tracker'!I4:I51)
B31: Avg Hourly Rate | C31: =IFERROR(D49/D48,0)
B32: Most Productive Day | C32: =TEXT(INDEX('⏱️ Time Tracker'!B4:B51,MATCH(MAX('⏱️ Time Tracker'!G4:G51),'⏱️ Time Tracker'!G4:G51,0)),"DD/MM/YYYY")
